import { describe, it, expect, vi } from 'vitest';
import { render, screen, fireEvent } from '@testing-library/react';
import { ErrorBoundary } from '@/components/ErrorBoundary';

// Component that throws an error
function ThrowError({ shouldThrow }: { shouldThrow: boolean }) {
  if (shouldThrow) {
    throw new Error('Test error');
  }
  return <div>No error</div>;
}

describe('ErrorBoundary', () => {
  it('renders children when there is no error', () => {
    render(
      <ErrorBoundary>
        <div>Test content</div>
      </ErrorBoundary>
    );

    expect(screen.getByText('Test content')).toBeInTheDocument();
  });

  it('displays error fallback when error occurs', () => {
    // Suppress console.error for this test
    const consoleSpy = vi.spyOn(console, 'error').mockImplementation(() => {});

    render(
      <ErrorBoundary>
        <ThrowError shouldThrow={true} />
      </ErrorBoundary>
    );

    expect(screen.getByText(/Something went wrong/i)).toBeInTheDocument();
    expect(screen.getByText(/Test error/i)).toBeInTheDocument();

    consoleSpy.mockRestore();
  });

  it('calls custom fallback function when provided', () => {
    const consoleSpy = vi.spyOn(console, 'error').mockImplementation(() => {});
    const customFallback = (error?: Error) => (
      <div>Custom error: {error?.message}</div>
    );

    render(
      <ErrorBoundary fallback={customFallback}>
        <ThrowError shouldThrow={true} />
      </ErrorBoundary>
    );

    expect(screen.getByText('Custom error: Test error')).toBeInTheDocument();

    consoleSpy.mockRestore();
  });

  it('allows retry after error', () => {
    const consoleSpy = vi.spyOn(console, 'error').mockImplementation(() => {});
    let shouldThrow = true;

    const { rerender } = render(
      <ErrorBoundary>
        <ThrowError shouldThrow={shouldThrow} />
      </ErrorBoundary>
    );

    expect(screen.getByText(/Something went wrong/i)).toBeInTheDocument();

    // Change the condition to not throw
    shouldThrow = false;

    // Click retry button
    const retryButton = screen.getByText(/Try Again/i);
    fireEvent.click(retryButton);

    // Rerender with new props
    rerender(
      <ErrorBoundary>
        <ThrowError shouldThrow={shouldThrow} />
      </ErrorBoundary>
    );

    expect(screen.getByText('No error')).toBeInTheDocument();

    consoleSpy.mockRestore();
  });

  it('calls onError callback when error occurs', () => {
    const consoleSpy = vi.spyOn(console, 'error').mockImplementation(() => {});
    const onError = vi.fn();

    render(
      <ErrorBoundary onError={onError}>
        <ThrowError shouldThrow={true} />
      </ErrorBoundary>
    );

    expect(onError).toHaveBeenCalledWith(
      expect.objectContaining({
        message: 'Test error',
      }),
      expect.objectContaining({
        componentStack: expect.any(String),
      })
    );

    consoleSpy.mockRestore();
  });
});